Workbook
Name Bercos: Parametros!$B$2:$B$6
Name Categorias_Parada: Parametros!$E$2:$E$10
Name Janelas: Parametros!$D$2:$D$5
Name Poroes: Parametros!$G$2:$G$13
Name Terminais: Parametros!$A$2:$A$5
Name Tipos_Operacao: Parametros!$F$2:$F$4
Name Turnos: Parametros!$C$2:$C$5

Sheet Instrucoes
A1: TORRE DE CONTROLE – PRODUTIVIDADE DE DESCARGA DE NAVIOS
A3: Objetivo | B3: Controlar produtividade de descarga por navio, turno e porão, com rastreabilidade de paradas e dashboard executivo.
A4: Lógica de captura | B4: 1) Cadastrar o navio em Cadastro_Navio. 2) Informar volumes manifestados por porão em Poroes_Resumo. 3) Lançar cada turno em Base_Porao_Turno. 4) Detalhar paradas em Paradas_Detalhadas. 5) Ler KPIs e Dashboard.
A5: Melhor prática para KPI | B5: O KPI deve nascer do menor nível operacional possível: turno + porão. Isso evita distorções de média e melhora a confiabilidade.
A6: Cores | B6: Azul = input manual | Preto = fórmula | Verde = resumo/consolidado | Roxo = controle.
A7: KPIs do modelo original | B7: ETB, ETS, Volume Navio, Volume Descarregado, Produtividade t/h, Média t/dia, Tempo Médio porão, Total Trabalhado, Total Paradas, % Parada Operacional, Eficiência Operacional e Total de Operação.

Sheet Parametros
A1: Terminais | B1: Bercos | C1: Turnos | D1: Janelas | E1: Categorias_Parada | F1: Tipos_Operacao | G1: Poroes
A2: Imbituba | B2: Berço 1 | C2: A | D2: 01x07 | E2: Clima | F2: Terminal | G2: 1
A3: Itaúna | B3: Berço 2 | C3: B | D3: 07x13 | E3: Equipamento | F3: Direto | G3: 2
A4: Criciúma | B4: Berço 3 | C4: C | D4: 13x19 | E4: Operacional | F4: Mista | G4: 3
A5: Açu | B5: Berço 4 | C5: D | D5: 19x01 | E5: Manutenção | G5: 4
B6: Berço 5 | E6: Aguardando Cliente | G6: 5
E7: Falta de caminhões | G7: 6
E8: Segurança | G8: 7
E9: Sem Energia | G9: 8
E10: Outros | G10: 9
G11: 10
G12: 11
G13: 12

Sheet Cadastro_Navio
A1: Operacao ID | B1: Navio | C1: IMO | D1: Bandeira | E1: Terminal | F1: Berço | G1: Produto | H1: Cliente | I1: ETB | J1: ETS | K1: Volume Manifestado (t) | L1: Qtd Porões | M1: Tipo Operação | N1: Meta Produtividade (t/h) | O1: Meta Descarga (t/dia) | P1: Observações
A2: OP-001 | B2: Magic Celeste | C2: 9735115 | D2: Ilhas Marshalls | E2: Imbituba | F2: Berço 1 | G2: Gipisita | H2: Minas Tranding Company | I2: 46198 | J2: 46203 | K2: 61027 | L2: 5 | M2: Terminal | N2: 550 | O2: 12000
A3: OP-002 | B3: Phoenician M | C3: 9450806 | D3: Panamá | E3: Imbituba | F3: Berço 3 | G3: Antracito | H3: Minas Tranding Company | I3: 46211 | J3: 46212 | K3: 10600 | L3: 2 | M3: Direto | N3: 350 | O3: 10600
A4: OP-003 | B4: IC Phoenix | C4: 9738961 | D4: Panamá | E4: Imbituba | F4: Berço 3 | G4: Petcoke | H4: Minas Tranding Company | I4: 46237 | J4: 46242 | K4: 44031.65 | L4: 4 | M4: Terminal | N4: 400 | O4: 8000

Sheet Base_Porao_Turno
A1: Operacao ID | B1: Data | C1: Turno | D1: Janela | E1: Porão | F1: Horas Calendário | G1: Horas Paradas | H1: Horas Trabalhadas | I1: Volume Terminal (t) | J1: Volume Direto (t) | K1: Volume Total (t) | L1: Produtividade Total (t/h) | M1: Produtividade Terminal (t/h) | N1: Produtividade Direto (t/h) | O1: Categoria Parada Principal | P1: Observações
A2: OP-001 | B2: 46198 | C2: A | D2: 07x13 | E2: 3 | F2: 6 | G2: =IF(A2="","",SUMIFS(Paradas_Detalhadas!$I:$I,Paradas_Detalhadas!$A:$A,A2,Paradas_Detalhadas!$B:$B,B2,Paradas_Detalhadas!$C:$C,C2,Paradas_Detalhadas!$D:$D,E2)) -> 1.9166667 | H2: =IF(OR(F2="",G2=""),"",MAX(F2-G2,0)) -> 4.0833333 | I2: 2115.42 | K2: =IF(AND(I2="",J2=""),"",SUM(I2:J2)) -> 2115.42 | L2: =IFERROR(K2/H2,"") -> 518.06204 | M2: =IFERROR(I2/H2,"") -> 518.06204 | N2: =IFERROR(J2/H2,"") -> 0 | O2: Operacional | P2: Importado do modelo
A3: OP-001 | B3: 46198 | C3: B | D3: 13x19 | E3: 3 | F3: 6 | G3: =IF(A3="","",SUMIFS(Paradas_Detalhadas!$I:$I,Paradas_Detalhadas!$A:$A,A3,Paradas_Detalhadas!$B:$B,B3,Paradas_Detalhadas!$C:$C,C3,Paradas_Detalhadas!$D:$D,E3)) -> 0.41666667 | H3: =IF(OR(F3="",G3=""),"",MAX(F3-G3,0)) -> 5.5833333 | I3: 2825.02 | J3: 0 | K3: =IF(AND(I3="",J3=""),"",SUM(I3:J3)) -> 2825.02 | L3: =IFERROR(K3/H3,"") -> 505.97373 | M3: =IFERROR(I3/H3,"") -> 505.97373 | N3: =IFERROR(J3/H3,"") -> 0 | O3: Operacional | P3: Importado do modelo
A4: OP-001 | B4: 46198 | C4: C | D4: 19x01 | E4: 3 | F4: 6 | G4: =IF(A4="","",SUMIFS(Paradas_Detalhadas!$I:$I,Paradas_Detalhadas!$A:$A,A4,Paradas_Detalhadas!$B:$B,B4,Paradas_Detalhadas!$C:$C,C4,Paradas_Detalhadas!$D:$D,E4)) -> 1.4166667 | H4: =IF(OR(F4="",G4=""),"",MAX(F4-G4,0)) -> 4.5833333 | I4: 2383.87 | J4: 0 | K4: =IF(AND(I4="",J4=""),"",SUM(I4:J4)) -> 2383.87 | L4: =IFERROR(K4/H4,"") -> 520.11709 | M4: =IFERROR(I4/H4,"") -> 520.11709 | N4: =IFERROR(J4/H4,"") -> 0 | O4: Operacional | P4: Importado do modelo
A5: OP-001 | B5: 46198 | C5: C | D5: 19x01 | E5: 5 | F5: 6 | G5: =IF(A5="","",SUMIFS(Paradas_Detalhadas!$I:$I,Paradas_Detalhadas!$A:$A,A5,Paradas_Detalhadas!$B:$B,B5,Paradas_Detalhadas!$C:$C,C5,Paradas_Detalhadas!$D:$D,E5)) -> 0.58333333 | H5: =IF(OR(F5="",G5=""),"",MAX(F5-G5,0)) -> 5.4166667 | I5: 2698.55 | K5: =IF(AND(I5="",J5=""),"",SUM(I5:J5)) -> 2698.55 | L5: =IFERROR(K5/H5,"") -> 498.19385 | M5: =IFERROR(I5/H5,"") -> 498.19385 | N5: =IFERROR(J5/H5,"") -> 0
A6: OP-001 | B6: 46199 | C6: D | D6: 01x07 | E6: 2 | F6: 6 | G6: =IF(A6="","",SUMIFS(Paradas_Detalhadas!$I:$I,Paradas_Detalhadas!$A:$A,A6,Paradas_Detalhadas!$B:$B,B6,Paradas_Detalhadas!$C:$C,C6,Paradas_Detalhadas!$D:$D,E6)) -> 1.25 | H6: =IF(OR(F6="",G6=""),"",MAX(F6-G6,0)) -> 4.75 | I6: 2550.9 | K6: =IF(AND(I6="",J6=""),"",SUM(I6:J6)) -> 2550.9 | L6: =IFERROR(K6/H6,"") -> 537.03158 | M6: =IFERROR(I6/H6,"") -> 537.03158 | N6: =IFERROR(J6/H6,"") -> 0
A7: OP-001 | B7: 46199 | C7: D | D7: 01x07 | E7: 5 | F7: 6 | G7: =IF(A7="","",SUMIFS(Paradas_Detalhadas!$I:$I,Paradas_Detalhadas!$A:$A,A7,Paradas_Detalhadas!$B:$B,B7,Paradas_Detalhadas!$C:$C,C7,Paradas_Detalhadas!$D:$D,E7)) -> 0.66666667 | H7: =IF(OR(F7="",G7=""),"",MAX(F7-G7,0)) -> 5.3333333 | I7: 1996.26 | K7: =IF(AND(I7="",J7=""),"",SUM(I7:J7)) -> 1996.26 | L7: =IFERROR(K7/H7,"") -> 374.29875 | M7: =IFERROR(I7/H7,"") -> 374.29875 | N7: =IFERROR(J7/H7,"") -> 0
A8: OP-001 | B8: 46199 | C8: A | D8: 07x13 | E8: 2 | F8: 6 | G8: =IF(A8="","",SUMIFS(Paradas_Detalhadas!$I:$I,Paradas_Detalhadas!$A:$A,A8,Paradas_Detalhadas!$B:$B,B8,Paradas_Detalhadas!$C:$C,C8,Paradas_Detalhadas!$D:$D,E8)) -> 1.4166667 | H8: =IF(OR(F8="",G8=""),"",MAX(F8-G8,0)) -> 4.5833333 | I8: 2295.18 | K8: =IF(AND(I8="",J8=""),"",SUM(I8:J8)) -> 2295.18 | L8: =IFERROR(K8/H8,"") -> 500.76655 | M8: =IFERROR(I8/H8,"") -> 500.76655 | N8: =IFERROR(J8/H8,"") -> 0
A9: OP-001 | B9: 46199 | C9: A | D9: 07x13 | E9: 5 | F9: 6 | G9: =IF(A9="","",SUMIFS(Paradas_Detalhadas!$I:$I,Paradas_Detalhadas!$A:$A,A9,Paradas_Detalhadas!$B:$B,B9,Paradas_Detalhadas!$C:$C,C9,Paradas_Detalhadas!$D:$D,E9)) -> 0.58333333 | H9: =IF(OR(F9="",G9=""),"",MAX(F9-G9,0)) -> 5.4166667 | I9: 2178 | K9: =IF(AND(I9="",J9=""),"",SUM(I9:J9)) -> 2178 | L9: =IFERROR(K9/H9,"") -> 402.09231 | M9: =IFERROR(I9/H9,"") -> 402.09231 | N9: =IFERROR(J9/H9,"") -> 0
A10: OP-001 | B10: 46199 | C10: B | D10: 13x19 | E10: 2 | F10: 6 | G10: =IF(A10="","",SUMIFS(Paradas_Detalhadas!$I:$I,Paradas_Detalhadas!$A:$A,A10,Paradas_Detalhadas!$B:$B,B10,Paradas_Detalhadas!$C:$C,C10,Paradas_Detalhadas!$D:$D,E10)) -> 0.5 | H10: =IF(OR(F10="",G10=""),"",MAX(F10-G10,0)) -> 5.5 | I10: 2356.89 | K10: =IF(AND(I10="",J10=""),"",SUM(I10:J10)) -> 2356.89 | L10: =IFERROR(K10/H10,"") -> 428.52545 | M10: =IFERROR(I10/H10,"") -> 428.52545 | N10: =IFERROR(J10/H10,"") -> 0
A11: OP-001 | B11: 46199 | C11: B | D11: 13x19 | E11: 5 | F11: 6 | G11: =IF(A11="","",SUMIFS(Paradas_Detalhadas!$I:$I,Paradas_Detalhadas!$A:$A,A11,Paradas_Detalhadas!$B:$B,B11,Paradas_Detalhadas!$C:$C,C11,Paradas_Detalhadas!$D:$D,E11)) -> 1.3333333 | H11: =IF(OR(F11="",G11=""),"",MAX(F11-G11,0)) -> 4.6666667 | I11: 1932.39 | K11: =IF(AND(I11="",J11=""),"",SUM(I11:J11)) -> 1932.39 | L11: =IFERROR(K11/H11,"") -> 414.08357 | M11: =IFERROR(I11/H11,"") -> 414.08357 | N11: =IFERROR(J11/H11,"") -> 0
A12: OP-001 | B12: 46199 | C12: C | D12: 19x01 | E12: 1 | F12: 6 | G12: =IF(A12="","",SUMIFS(Paradas_Detalhadas!$I:$I,Paradas_Detalhadas!$A:$A,A12,Paradas_Detalhadas!$B:$B,B12,Paradas_Detalhadas!$C:$C,C12,Paradas_Detalhadas!$D:$D,E12)) -> 0.5 | H12: =IF(OR(F12="",G12=""),"",MAX(F12-G12,0)) -> 5.5 | I12: 1476.13 | K12: =IF(AND(I12="",J12=""),"",SUM(I12:J12)) -> 1476.13 | L12: =IFERROR(K12/H12,"") -> 268.38727 | M12: =IFERROR(I12/H12,"") -> 268.38727 | N12: =IFERROR(J12/H12,"") -> 0
A13: OP-001 | B13: 46199 | C13: C | D13: 19x01 | E13: 2 | F13: 6 | G13: =IF(A13="","",SUMIFS(Paradas_Detalhadas!$I:$I,Paradas_Detalhadas!$A:$A,A13,Paradas_Detalhadas!$B:$B,B13,Paradas_Detalhadas!$C:$C,C13,Paradas_Detalhadas!$D:$D,E13)) -> 0.5 | H13: =IF(OR(F13="",G13=""),"",MAX(F13-G13,0)) -> 5.5 | I13: 821.18 | K13: =IF(AND(I13="",J13=""),"",SUM(I13:J13)) -> 821.18 | L13: =IFERROR(K13/H13,"") -> 149.30545 | M13: =IFERROR(I13/H13,"") -> 149.30545 | N13: =IFERROR(J13/H13,"") -> 0
A14: OP-001 | B14: 46199 | C14: C | D14: 13x19 | E14: 4 | F14: 6 | G14: =IF(A14="","",SUMIFS(Paradas_Detalhadas!$I:$I,Paradas_Detalhadas!$A:$A,A14,Paradas_Detalhadas!$B:$B,B14,Paradas_Detalhadas!$C:$C,C14,Paradas_Detalhadas!$D:$D,E14)) -> 0.16666667 | H14: =IF(OR(F14="",G14=""),"",MAX(F14-G14,0)) -> 5.8333333 | I14: 2937.87 | K14: =IF(AND(I14="",J14=""),"",SUM(I14:J14)) -> 2937.87 | L14: =IFERROR(K14/H14,"") -> 503.63486 | M14: =IFERROR(I14/H14,"") -> 503.63486 | N14: =IFERROR(J14/H14,"") -> 0
A15: OP-001 | B15: 46200 | C15: D | D15: 01x07 | E15: 1 | F15: 6 | G15: =IF(A15="","",SUMIFS(Paradas_Detalhadas!$I:$I,Paradas_Detalhadas!$A:$A,A15,Paradas_Detalhadas!$B:$B,B15,Paradas_Detalhadas!$C:$C,C15,Paradas_Detalhadas!$D:$D,E15)) -> 0.91666667 | H15: =IF(OR(F15="",G15=""),"",MAX(F15-G15,0)) -> 5.0833333 | I15: 2404.29 | K15: =IF(AND(I15="",J15=""),"",SUM(I15:J15)) -> 2404.29 | L15: =IFERROR(K15/H15,"") -> 472.97508 | M15: =IFERROR(I15/H15,"") -> 472.97508 | N15: =IFERROR(J15/H15,"") -> 0
A16: OP-001 | B16: 46200 | C16: D | D16: 01x07 | E16: 4 | F16: 6 | G16: =IF(A16="","",SUMIFS(Paradas_Detalhadas!$I:$I,Paradas_Detalhadas!$A:$A,A16,Paradas_Detalhadas!$B:$B,B16,Paradas_Detalhadas!$C:$C,C16,Paradas_Detalhadas!$D:$D,E16)) -> 0.75 | H16: =IF(OR(F16="",G16=""),"",MAX(F16-G16,0)) -> 5.25 | I16: 2550.17 | K16: =IF(AND(I16="",J16=""),"",SUM(I16:J16)) -> 2550.17 | L16: =IFERROR(K16/H16,"") -> 485.74667 | M16: =IFERROR(I16/H16,"") -> 485.74667 | N16: =IFERROR(J16/H16,"") -> 0
... A39: OP-001 | B39: 46202 | C39: D | D39: 01x07 | E39: 4 | F39: 4 | G39: =IF(A39="","",SUMIFS(Paradas_Detalhadas!$I:$I,Paradas_Detalhadas!$A:$A,A39,Paradas_Detalhadas!$B:$B,B39,Paradas_Detalhadas!$C:$C,C39,Paradas_Detalhadas!$D:$D,E39)) -> 0 | H39: =IF(OR(F39="",G39=""),"",MAX(F39-G39,0)) -> 4 | I39: 50.96 | K39: =IF(AND(I39="",J39=""),"",SUM(I39:J39)) -> 50.96 | L39: =IFERROR(K39/H39,"") -> 12.74 | M39: =IFERROR(I39/H39,"") -> 12.74 | N39: =IFERROR(J39/H39,"") -> 0
A40: OP-002 | B40: 46211 | C40: C | D40: 19x01 | E40: 2 | F40: 6 | G40: 0.71666667 | H40: 5.2833333 | J40: 1590.87 | K40: 1590.87 | L40: 301.11104 | M40: 0 | N40: 301.11104 | O40: Outros
A41: OP-002 | B41: 46212 | C41: D | D41: 01x07 | E41: 2 | F41: 6 | G41: 2.1666667 | H41: 3.8333333 | J41: 1743.76 | K41: 1743.76 | L41: 454.89391 | M41: 0 | N41: 454.89391 | O41: Segurança
A42: OP-002 | B42: 46212 | C42: A | D42: 07x13 | E42: 4 | F42: 6 | G42: 0.91666667 | H42: 5.0833333 | J42: 2042.14 | K42: 2042.14 | L42: 401.73246 | M42: 0 | N42: 401.73246 | O42: Falta de caminhões
A43: OP-002 | B43: 46212 | C43: B | D43: 13x19 | E43: 4 | F43: 6 | G43: 1.4166667 | H43: 4.5833333 | J43: 1733.57 | K43: 1733.57 | L43: 378.23345 | M43: 0 | N43: 378.23345 | O43: Segurança
A44: OP-002 | B44: 46212 | C44: C | D44: 19x01 | E44: 4 | F44: 6 | G44: 1 | H44: 5 | J44: 2076.87 | K44: 2076.87 | L44: 415.374 | M44: 0 | N44: 415.374 | O44: Segurança
A45: OP-002 | B45: 46213 | C45: D | D45: 01x07 | E45: 4 | F45: 6 | G45: 2.4166667 | H45: 3.5833333 | J45: 1600.49 | K45: 1600.49 | L45: 446.64837 | M45: 0 | N45: 446.64837 | O45: Segurança
A46: OP-002 | B46: 46213 | C46: A | D46: 07x13 | E46: 4 | F46: 4 | G46: =IF(A46="","",SUMIFS(Paradas_Detalhadas!$I:$I,Paradas_Detalhadas!$A:$A,A46,Paradas_Detalhadas!$B:$B,B46,Paradas_Detalhadas!$C:$C,C46,Paradas_Detalhadas!$D:$D,E46)) -> 2 | H46: =IF(OR(F46="",G46=""),"",MAX(F46-G46,0)) -> 2 | J46: 400.85 | K46: =IF(AND(I46="",J46=""),"",SUM(I46:J46)) -> 400.85 | L46: =IFERROR(K46/H46,"") -> 200.425 | M46: =IFERROR(I46/H46,"") -> 0 | N46: =IFERROR(J46/H46,"") -> 200.425
A47: OP-003 | B47: 46237 | C47: C | D47: 19x01 | E47: 2 | F47: 6 | G47: =IF(A47="","",SUMIFS(Paradas_Detalhadas!$I:$I,Paradas_Detalhadas!$A:$A,A47,Paradas_Detalhadas!$B:$B,B47,Paradas_Detalhadas!$C:$C,C47,Paradas_Detalhadas!$D:$D,E47)) -> 0.16666667 | H47: =IF(OR(F47="",G47=""),"",MAX(F47-G47,0)) -> 5.8333333 | I47: 2219.11 | K47: =IF(AND(I47="",J47=""),"",SUM(I47:J47)) -> 2219.11 | L47: =IFERROR(K47/H47,"") -> 380.41886 | M47: =IFERROR(I47/H47,"") -> 380.41886 | N47: =IFERROR(J47/H47,"") -> 0
A48: OP-003 | B48: 46238 | C48: D | D48: 01x07 | E48: 2 | F48: 6 | G48: =IF(A48="","",SUMIFS(Paradas_Detalhadas!$I:$I,Paradas_Detalhadas!$A:$A,A48,Paradas_Detalhadas!$B:$B,B48,Paradas_Detalhadas!$C:$C,C48,Paradas_Detalhadas!$D:$D,E48)) -> 0.16666667 | H48: =IF(OR(F48="",G48=""),"",MAX(F48-G48,0)) -> 5.8333333 | I48: 2115.07 | K48: =IF(AND(I48="",J48=""),"",SUM(I48:J48)) -> 2115.07 | L48: =IFERROR(K48/H48,"") -> 362.58343 | M48: =IFERROR(I48/H48,"") -> 362.58343 | N48: =IFERROR(J48/H48,"") -> 0
A49: OP-003 | B49: 46238 | C49: A | D49: 07x13 | E49: 2 | F49: 6 | G49: =IF(A49="","",SUMIFS(Paradas_Detalhadas!$I:$I,Paradas_Detalhadas!$A:$A,A49,Paradas_Detalhadas!$B:$B,B49,Paradas_Detalhadas!$C:$C,C49,Paradas_Detalhadas!$D:$D,E49)) -> 0.83333333 | H49: =IF(OR(F49="",G49=""),"",MAX(F49-G49,0)) -> 5.1666667 | I49: 2013.59 | K49: =IF(AND(I49="",J49=""),"",SUM(I49:J49)) -> 2013.59 | L49: =IFERROR(K49/H49,"") -> 389.7271 | M49: =IFERROR(I49/H49,"") -> 389.7271 | N49: =IFERROR(J49/H49,"") -> 0
G50: =IF(A50="","",SUMIFS(Paradas_Detalhadas!$I:$I,Paradas_Detalhadas!$A:$A,A50,Paradas_Detalhadas!$B:$B,B50,Paradas_Detalhadas!$C:$C,C50,Paradas_Detalhadas!$D:$D,E50)) | H50: =IF(OR(F50="",G50=""),"",MAX(F50-G50,0)) | K50: =IF(AND(I50="",J50=""),"",SUM(I50:J50)) | L50: =IFERROR(K50/H50,"") | M50: =IFERROR(I50/H50,"") | N50: =IFERROR(J50/H50,"")
G51: =IF(A51="","",SUMIFS(Paradas_Detalhadas!$I:$I,Paradas_Detalhadas!$A:$A,A51,Paradas_Detalhadas!$B:$B,B51,Paradas_Detalhadas!$C:$C,C51,Paradas_Detalhadas!$D:$D,E51)) | H51: =IF(OR(F51="",G51=""),"",MAX(F51-G51,0)) | K51: =IF(AND(I51="",J51=""),"",SUM(I51:J51)) | L51: =IFERROR(K51/H51,"") | M51: =IFERROR(I51/H51,"") | N51: =IFERROR(J51/H51,"")
G52: =IF(A52="","",SUMIFS(Paradas_Detalhadas!$I:$I,Paradas_Detalhadas!$A:$A,A52,Paradas_Detalhadas!$B:$B,B52,Paradas_Detalhadas!$C:$C,C52,Paradas_Detalhadas!$D:$D,E52)) | H52: =IF(OR(F52="",G52=""),"",MAX(F52-G52,0)) | K52: =IF(AND(I52="",J52=""),"",SUM(I52:J52)) | L52: =IFERROR(K52/H52,"") | M52: =IFERROR(I52/H52,"") | N52: =IFERROR(J52/H52,"")
G53: =IF(A53="","",SUMIFS(Paradas_Detalhadas!$I:$I,Paradas_Detalhadas!$A:$A,A53,Paradas_Detalhadas!$B:$B,B53,Paradas_Detalhadas!$C:$C,C53,Paradas_Detalhadas!$D:$D,E53)) | H53: =IF(OR(F53="",G53=""),"",MAX(F53-G53,0)) | K53: =IF(AND(I53="",J53=""),"",SUM(I53:J53)) | L53: =IFERROR(K53/H53,"") | M53: =IFERROR(I53/H53,"") | N53: =IFERROR(J53/H53,"")
G54: =IF(A54="","",SUMIFS(Paradas_Detalhadas!$I:$I,Paradas_Detalhadas!$A:$A,A54,Paradas_Detalhadas!$B:$B,B54,Paradas_Detalhadas!$C:$C,C54,Paradas_Detalhadas!$D:$D,E54)) | H54: =IF(OR(F54="",G54=""),"",MAX(F54-G54,0)) | K54: =IF(AND(I54="",J54=""),"",SUM(I54:J54)) | L54: =IFERROR(K54/H54,"") | M54: =IFERROR(I54/H54,"") | N54: =IFERROR(J54/H54,"")
G55: =IF(A55="","",SUMIFS(Paradas_Detalhadas!$I:$I,Paradas_Detalhadas!$A:$A,A55,Paradas_Detalhadas!$B:$B,B55,Paradas_Detalhadas!$C:$C,C55,Paradas_Detalhadas!$D:$D,E55)) | H55: =IF(OR(F55="",G55=""),"",MAX(F55-G55,0)) | K55: =IF(AND(I55="",J55=""),"",SUM(I55:J55)) | L55: =IFERROR(K55/H55,"") | M55: =IFERROR(I55/H55,"") | N55: =IFERROR(J55/H55,"")
G56: =IF(A56="","",SUMIFS(Paradas_Detalhadas!$I:$I,Paradas_Detalhadas!$A:$A,A56,Paradas_Detalhadas!$B:$B,B56,Paradas_Detalhadas!$C:$C,C56,Paradas_Detalhadas!$D:$D,E56)) | H56: =IF(OR(F56="",G56=""),"",MAX(F56-G56,0)) | K56: =IF(AND(I56="",J56=""),"",SUM(I56:J56)) | L56: =IFERROR(K56/H56,"") | M56: =IFERROR(I56/H56,"") | N56: =IFERROR(J56/H56,"")
G57: =IF(A57="","",SUMIFS(Paradas_Detalhadas!$I:$I,Paradas_Detalhadas!$A:$A,A57,Paradas_Detalhadas!$B:$B,B57,Paradas_Detalhadas!$C:$C,C57,Paradas_Detalhadas!$D:$D,E57)) | H57: =IF(OR(F57="",G57=""),"",MAX(F57-G57,0)) | K57: =IF(AND(I57="",J57=""),"",SUM(I57:J57)) | L57: =IFERROR(K57/H57,"") | M57: =IFERROR(I57/H57,"") | N57: =IFERROR(J57/H57,"")
G58: =IF(A58="","",SUMIFS(Paradas_Detalhadas!$I:$I,Paradas_Detalhadas!$A:$A,A58,Paradas_Detalhadas!$B:$B,B58,Paradas_Detalhadas!$C:$C,C58,Paradas_Detalhadas!$D:$D,E58)) | H58: =IF(OR(F58="",G58=""),"",MAX(F58-G58,0)) | K58: =IF(AND(I58="",J58=""),"",SUM(I58:J58)) | L58: =IFERROR(K58/H58,"") | M58: =IFERROR(I58/H58,"") | N58: =IFERROR(J58/H58,"")
G59: =IF(A59="","",SUMIFS(Paradas_Detalhadas!$I:$I,Paradas_Detalhadas!$A:$A,A59,Paradas_Detalhadas!$B:$B,B59,Paradas_Detalhadas!$C:$C,C59,Paradas_Detalhadas!$D:$D,E59)) | H59: =IF(OR(F59="",G59=""),"",MAX(F59-G59,0)) | K59: =IF(AND(I59="",J59=""),"",SUM(I59:J59)) | L59: =IFERROR(K59/H59,"") | M59: =IFERROR(I59/H59,"") | N59: =IFERROR(J59/H59,"")
G60: =IF(A60="","",SUMIFS(Paradas_Detalhadas!$I:$I,Paradas_Detalhadas!$A:$A,A60,Paradas_Detalhadas!$B:$B,B60,Paradas_Detalhadas!$C:$C,C60,Paradas_Detalhadas!$D:$D,E60)) | H60: =IF(OR(F60="",G60=""),"",MAX(F60-G60,0)) | K60: =IF(AND(I60="",J60=""),"",SUM(I60:J60)) | L60: =IFERROR(K60/H60,"") | M60: =IFERROR(I60/H60,"") | N60: =IFERROR(J60/H60,"")
G61: =IF(A61="","",SUMIFS(Paradas_Detalhadas!$I:$I,Paradas_Detalhadas!$A:$A,A61,Paradas_Detalhadas!$B:$B,B61,Paradas_Detalhadas!$C:$C,C61,Paradas_Detalhadas!$D:$D,E61)) | H61: =IF(OR(F61="",G61=""),"",MAX(F61-G61,0)) | K61: =IF(AND(I61="",J61=""),"",SUM(I61:J61)) | L61: =IFERROR(K61/H61,"") | M61: =IFERROR(I61/H61,"") | N61: =IFERROR(J61/H61,"")
... G1501: =IF(A1501="","",SUMIFS(Paradas_Detalhadas!$I:$I,Paradas_Detalhadas!$A:$A,A1501,Paradas_Detalhadas!$B:$B,B1501,Paradas_Detalhadas!$C:$C,C1501,Paradas_Detalhadas!$D:$D,E1501)) | H1501: =IF(OR(F1501="",G1501=""),"",MAX(F1501-G1501,0)) | K1501: =IF(AND(I1501="",J1501=""),"",SUM(I1501:J1501)) | L1501: =IFERROR(K1501/H1501,"") | M1501: =IFERROR(I1501/H1501,"") | N1501: =IFERROR(J1501/H1501,"")

Sheet Paradas_Detalhadas
A1: Operacao ID | B1: Data | C1: Turno | D1: Porão | E1: Categoria | F1: Motivo | G1: Início | H1: Fim | I1: Horas Paradas | J1: Responsável | K1: Impacto
A2: OP-001 | B2: 46198 | C2: A | D2: 3 | E2: Operacional | F2: Inicio Operação | G2: 0.29166667 | H2: 0.35416667 | I2: =IF(AND(G2<>"",H2<>""),MOD(H2-G2,1)*24,"") -> 1.5 | J2: Operação cais
A3: OP-001 | B3: 46198 | C3: A | D3: 3 | E3: Equipamento | F3: translado guindastes | G3: 0.40277778 | H3: 0.42013889 | I3: =IF(AND(G3<>"",H3<>""),MOD(H3-G3,1)*24,"") -> 0.41666667 | J3: Operação cais
A4: OP-001 | B4: 46198 | C4: B | D4: 3 | E4: Segurança | F4: DDS | G4: 0.54166667 | H4: 0.54861111 | I4: =IF(AND(G4<>"",H4<>""),MOD(H4-G4,1)*24,"") -> 0.16666667 | J4: Operação cais
A5: OP-001 | B5: 46198 | C5: B | D5: 3 | E5: Operacional | F5: Colocar escavadeira no porão | G5: 0.64930556 | H5: 0.65972222 | I5: =IF(AND(G5<>"",H5<>""),MOD(H5-G5,1)*24,"") -> 0.25 | J5: Operação cais
A6: OP-001 | B6: 46198 | C6: C | D6: 3 | E6: Operacional | F6: escavadeira porão e movimentaçoes | G6: 0.79166667 | H6: 0.85069444 | I6: =IF(AND(G6<>"",H6<>""),MOD(H6-G6,1)*24,"") -> 1.4166667 | J6: Operação cais
A7: OP-001 | B7: 46198 | C7: C | D7: 5 | E7: Operacional | F7: DDS movimentação maquinas | G7: 0.79166667 | H7: 0.81597222 | I7: =IF(AND(G7<>"",H7<>""),MOD(H7-G7,1)*24,"") -> 0.58333333 | J7: Operação cais
A8: OP-001 | B8: 46199 | C8: D | D8: 2 | E8: Operacional | F8: Aguardando caminhoes | G8: 0.083333333 | H8: 0.13541667 | I8: =IF(AND(G8<>"",H8<>""),MOD(H8-G8,1)*24,"") -> 1.25 | J8: Operação cais
A9: OP-001 | B9: 46199 | C9: D | D9: 5 | E9: Equipamento | F9: Aguardando caminhoes | G9: 0.125 | H9: 0.15277778 | I9: =IF(AND(G9<>"",H9<>""),MOD(H9-G9,1)*24,"") -> 0.66666667 | J9: Operação cais
A10: OP-001 | B10: 46199 | C10: A | D10: 2 | E10: Operacional | F10: diversas | G10: 0.29166667 | H10: 0.35069444 | I10: =IF(AND(G10<>"",H10<>""),MOD(H10-G10,1)*24,"") -> 1.4166667 | J10: Operação cais
A11: OP-001 | B11: 46199 | C11: A | D11: 5 | E11: Operacional | F11: diversas | G11: 0.29166667 | H11: 0.31597222 | I11: =IF(AND(G11<>"",H11<>""),MOD(H11-G11,1)*24,"") -> 0.58333333 | J11: Operação cais
A12: OP-001 | B12: 46199 | C12: B | D12: 2 | E12: Operacional | F12: diversas | G12: 0.54166667 | H12: 0.5625 | I12: =IF(AND(G12<>"",H12<>""),MOD(H12-G12,1)*24,"") -> 0.5 | J12: Operação cais
A13: OP-001 | B13: 46199 | C13: B | D13: 5 | E13: Operacional | F13: diversas | G13: 0.66666667 | H13: 0.72222222 | I13: =IF(AND(G13<>"",H13<>""),MOD(H13-G13,1)*24,"") -> 1.3333333 | J13: Operação cais
... A40: OP-001 | B40: 46201 | C40: D | D40: 4 | E40: Operacional | F40: diversas | G40: 0.041666667 | H40: 0.055555556 | I40: =IF(AND(G40<>"",H40<>""),MOD(H40-G40,1)*24,"") -> 0.33333333 | J40: Operação cais
A41: OP-002 | B41: 46211 | C41: C | D41: 2 | E41: Outros | F41: aguardando inicio operação | G41: 0.79166667 | H41: 0.81458333 | I41: 0.55 | J41: Operação cais
A42: OP-002 | B42: 46211 | C42: C | D42: 2 | E42: Segurança | F42: DDS | G42: 0.79166667 | H42: 0.79861111 | I42: 0.16666667 | J42: Operação cais
A43: OP-002 | B43: 46212 | C43: D | D43: 2 | E43: Segurança | F43: DDS | G43: 0.041666667 | H43: 0.048611111 | I43: 0.16666667 | J43: Operação cais
A44: OP-002 | B44: 46212 | C44: D | D44: 2 | E44: Operacional | F44: rechego porão | G44: 0.14930556 | H44: 0.23263889 | I44: 2 | J44: Operação cais
A45: OP-002 | B45: 46212 | C45: A | D45: 4 | E45: Falta de caminhões | F45: falta de caminhoes | G45: 0.5 | H45: 0.53125 | I45: 0.75 | J45: Operação cais
A46: OP-002 | B46: 46212 | C46: A | D46: 4 | E46: Segurança | F46: DDS | G46: 0.29166667 | H46: 0.29861111 | I46: 0.16666667 | J46: Operação cais
A47: OP-002 | B47: 46212 | C47: B | D47: 4 | E47: Segurança | F47: DDS | G47: 0.54166667 | H47: 0.54861111 | I47: 0.16666667 | J47: Operação cais
A48: OP-002 | B48: 46212 | C48: B | D48: 4 | E48: Falta de caminhões | F48: falta de caminhoes | G48: 0.625 | H48: 0.67708333 | I48: 1.25 | J48: Operação cais
A49: OP-002 | B49: 46212 | C49: C | D49: 4 | E49: Segurança | F49: DDS | G49: 0.79166667 | H49: 0.79861111 | I49: 0.16666667 | J49: Operação cais
A50: OP-002 | B50: 46212 | C50: C | D50: 4 | E50: Falta de caminhões | F50: falta de caminhoes | G50: 0 | H50: 0.034722222 | I50: 0.83333333 | J50: Operação cais
A51: OP-002 | B51: 46213 | C51: D | D51: 4 | E51: Segurança | F51: DDS | G51: 0.041666667 | H51: 0.048611111 | I51: 0.16666667 | J51: Operação cais
A52: OP-002 | B52: 46213 | C52: D | D52: 4 | E52: Falta de caminhões | F52: falta de caminhoes | G52: 0.19791667 | H52: 0.29166667 | I52: 2.25 | J52: Operação cais
A53: OP-002 | B53: 46213 | C53: A | D53: 4 | E53: Falta de caminhões | F53: falta de caminhoes | G53: 0.375 | H53: 0.45833333 | I53: =IF(AND(G53<>"",H53<>""),MOD(H53-G53,1)*24,"") -> 2 | J53: Operação cais
A54: OP-003 | B54: 46237 | C54: C | D54: 2 | E54: Segurança | F54: DDS | G54: 0.79166667 | H54: 0.79861111 | I54: =IF(AND(G54<>"",H54<>""),MOD(H54-G54,1)*24,"") -> 0.16666667 | J54: Operação cais
A55: OP-003 | B55: 46238 | C55: D | D55: 2 | E55: Segurança | F55: DDS | G55: 0.041666667 | H55: 0.048611111 | I55: =IF(AND(G55<>"",H55<>""),MOD(H55-G55,1)*24,"") -> 0.16666667 | J55: Operação cais
A56: OP-003 | B56: 46238 | C56: A | D56: 2 | E56: Segurança | F56: DDS | G56: 0.29166667 | H56: 0.29861111 | I56: =IF(AND(G56<>"",H56<>""),MOD(H56-G56,1)*24,"") -> 0.16666667 | J56: Operação cais
A57: OP-003 | B57: 46238 | C57: A | D57: 2 | E57: Clima | F57: Chuva | G57: 0.40625 | H57: 0.41319444 | I57: =IF(AND(G57<>"",H57<>""),MOD(H57-G57,1)*24,"") -> 0.16666667 | J57: Navio
A58: OP-003 | B58: 46238 | C58: A | D58: 2 | E58: Operacional | F58: Posicionar Guindastes | G58: 0.51388889 | H58: 0.53472222 | I58: =IF(AND(G58<>"",H58<>""),MOD(H58-G58,1)*24,"") -> 0.5 | J58: Operação cais
I59: =IF(AND(G59<>"",H59<>""),MOD(H59-G59,1)*24,"")
I60: =IF(AND(G60<>"",H60<>""),MOD(H60-G60,1)*24,"")
I61: =IF(AND(G61<>"",H61<>""),MOD(H61-G61,1)*24,"")
I62: =IF(AND(G62<>"",H62<>""),MOD(H62-G62,1)*24,"")
I63: =IF(AND(G63<>"",H63<>""),MOD(H63-G63,1)*24,"")
I64: =IF(AND(G64<>"",H64<>""),MOD(H64-G64,1)*24,"")
I65: =IF(AND(G65<>"",H65<>""),MOD(H65-G65,1)*24,"")
I66: =IF(AND(G66<>"",H66<>""),MOD(H66-G66,1)*24,"")
...

Sheet Poroes_Resumo
A1: Operacao ID | B1: Porão | C1: Volume Manifestado (t) | D1: Volume Descargado (t) | E1: Saldo (t) | F1: % Descarga | G1: Horas Trabalhadas | H1: Produtividade Média (t/h)
A2: OP-001 | B2: 1 | C2: 9171 | D2: =IF(A2="","",SUMIFS(Base_Porao_Turno!$K:$K,Base_Porao_Turno!$A:$A,A2,Base_Porao_Turno!$E:$E,B2)) -> 7974.63 | E2: =IF(OR(C2="",D2=""),"",C2-D2) -> 1196.37 | F2: =IFERROR(D2/C2,"") -> 0.86954858 | G2: =IF(A2="","",SUMIFS(Base_Porao_Turno!$H:$H,Base_Porao_Turno!$A:$A,A2,Base_Porao_Turno!$E:$E,B2)) -> 26.416667 | H2: =IFERROR(D2/G2,"") -> 301.87874
A3: OP-001 | B3: 2 | C3: 11671 | D3: =IF(A3="","",SUMIFS(Base_Porao_Turno!$K:$K,Base_Porao_Turno!$A:$A,A3,Base_Porao_Turno!$E:$E,B3)) -> 10512.02 | E3: =IF(OR(C3="",D3=""),"",C3-D3) -> 1158.98 | F3: =IFERROR(D3/C3,"") -> 0.90069574 | G3: =IF(A3="","",SUMIFS(Base_Porao_Turno!$H:$H,Base_Porao_Turno!$A:$A,A3,Base_Porao_Turno!$E:$E,B3)) -> 36.666667 | H3: =IFERROR(D3/G3,"") -> 286.69145
A4: OP-001 | B4: 3 | C4: 13457 | D4: =IF(A4="","",SUMIFS(Base_Porao_Turno!$K:$K,Base_Porao_Turno!$A:$A,A4,Base_Porao_Turno!$E:$E,B4)) -> 14959.33 | E4: =IF(OR(C4="",D4=""),"",C4-D4) -> -1502.33 | F4: =IFERROR(D4/C4,"") -> 1.1116393 | G4: =IF(A4="","",SUMIFS(Base_Porao_Turno!$H:$H,Base_Porao_Turno!$A:$A,A4,Base_Porao_Turno!$E:$E,B4)) -> 44.666667 | H4: =IFERROR(D4/G4,"") -> 334.91037
A5: OP-001 | B5: 4 | C5: 13981 | D5: =IF(A5="","",SUMIFS(Base_Porao_Turno!$K:$K,Base_Porao_Turno!$A:$A,A5,Base_Porao_Turno!$E:$E,B5)) -> 15414.75 | E5: =IF(OR(C5="",D5=""),"",C5-D5) -> -1433.75 | F5: =IFERROR(D5/C5,"") -> 1.1025499 | G5: =IF(A5="","",SUMIFS(Base_Porao_Turno!$H:$H,Base_Porao_Turno!$A:$A,A5,Base_Porao_Turno!$E:$E,B5)) -> 45.5 | H5: =IFERROR(D5/G5,"") -> 338.78571
A6: OP-001 | B6: 5 | C6: 12747 | D6: =IF(A6="","",SUMIFS(Base_Porao_Turno!$K:$K,Base_Porao_Turno!$A:$A,A6,Base_Porao_Turno!$E:$E,B6)) -> 11379.71 | E6: =IF(OR(C6="",D6=""),"",C6-D6) -> 1367.29 | F6: =IFERROR(D6/C6,"") -> 0.89273633 | G6: =IF(A6="","",SUMIFS(Base_Porao_Turno!$H:$H,Base_Porao_Turno!$A:$A,A6,Base_Porao_Turno!$E:$E,B6)) -> 41.75 | H6: =IFERROR(D6/G6,"") -> 272.5679
A7: OP-002 | B7: 2 | C7: 2900 | D7: =IF(A7="","",SUMIFS(Base_Porao_Turno!$K:$K,Base_Porao_Turno!$A:$A,A7,Base_Porao_Turno!$E:$E,B7)) -> 3334.63 | E7: =IF(OR(C7="",D7=""),"",C7-D7) -> -434.63 | F7: =IFERROR(D7/C7,"") -> 1.1498724 | G7: =IF(A7="","",SUMIFS(Base_Porao_Turno!$H:$H,Base_Porao_Turno!$A:$A,A7,Base_Porao_Turno!$E:$E,B7)) -> 9.1166667 | H7: =IFERROR(D7/G7,"") -> 365.77294
A8: OP-002 | B8: 4 | C8: 7700 | D8: =IF(A8="","",SUMIFS(Base_Porao_Turno!$K:$K,Base_Porao_Turno!$A:$A,A8,Base_Porao_Turno!$E:$E,B8)) -> 7853.92 | E8: =IF(OR(C8="",D8=""),"",C8-D8) -> -153.92 | F8: =IFERROR(D8/C8,"") -> 1.0199896 | G8: =IF(A8="","",SUMIFS(Base_Porao_Turno!$H:$H,Base_Porao_Turno!$A:$A,A8,Base_Porao_Turno!$E:$E,B8)) -> 20.25 | H8: =IFERROR(D8/G8,"") -> 387.8479
A9: OP-003 | B9: 1 | C9: 10939.98 | D9: =IF(A9="","",SUMIFS(Base_Porao_Turno!$K:$K,Base_Porao_Turno!$A:$A,A9,Base_Porao_Turno!$E:$E,B9)) -> 0 | E9: =IF(OR(C9="",D9=""),"",C9-D9) -> 10939.98 | F9: =IFERROR(D9/C9,"") -> 0 | G9: =IF(A9="","",SUMIFS(Base_Porao_Turno!$H:$H,Base_Porao_Turno!$A:$A,A9,Base_Porao_Turno!$E:$E,B9)) -> 0 | H9: =IFERROR(D9/G9,"")
A10: OP-003 | B10: 2 | C10: 11393.14 | D10: =IF(A10="","",SUMIFS(Base_Porao_Turno!$K:$K,Base_Porao_Turno!$A:$A,A10,Base_Porao_Turno!$E:$E,B10)) -> 6347.77 | E10: =IF(OR(C10="",D10=""),"",C10-D10) -> 5045.37 | F10: =IFERROR(D10/C10,"") -> 0.5571572 | G10: =IF(A10="","",SUMIFS(Base_Porao_Turno!$H:$H,Base_Porao_Turno!$A:$A,A10,Base_Porao_Turno!$E:$E,B10)) -> 16.833333 | H10: =IFERROR(D10/G10,"") -> 377.09525
A11: OP-003 | B11: 4 | C11: 10802.34 | D11: =IF(A11="","",SUMIFS(Base_Porao_Turno!$K:$K,Base_Porao_Turno!$A:$A,A11,Base_Porao_Turno!$E:$E,B11)) -> 0 | E11: =IF(OR(C11="",D11=""),"",C11-D11) -> 10802.34 | F11: =IFERROR(D11/C11,"") -> 0 | G11: =IF(A11="","",SUMIFS(Base_Porao_Turno!$H:$H,Base_Porao_Turno!$A:$A,A11,Base_Porao_Turno!$E:$E,B11)) -> 0 | H11: =IFERROR(D11/G11,"")
A12: OP-003 | B12: 5 | C12: 10896.19 | D12: =IF(A12="","",SUMIFS(Base_Porao_Turno!$K:$K,Base_Porao_Turno!$A:$A,A12,Base_Porao_Turno!$E:$E,B12)) -> 0 | E12: =IF(OR(C12="",D12=""),"",C12-D12) -> 10896.19 | F12: =IFERROR(D12/C12,"") -> 0 | G12: =IF(A12="","",SUMIFS(Base_Porao_Turno!$H:$H,Base_Porao_Turno!$A:$A,A12,Base_Porao_Turno!$E:$E,B12)) -> 0 | H12: =IFERROR(D12/G12,"")
D13: =IF(A13="","",SUMIFS(Base_Porao_Turno!$K:$K,Base_Porao_Turno!$A:$A,A13,Base_Porao_Turno!$E:$E,B13)) | E13: =IF(OR(C13="",D13=""),"",C13-D13) | F13: =IFERROR(D13/C13,"") | G13: =IF(A13="","",SUMIFS(Base_Porao_Turno!$H:$H,Base_Porao_Turno!$A:$A,A13,Base_Porao_Turno!$E:$E,B13)) | H13: =IFERROR(D13/G13,"")
D14: =IF(A14="","",SUMIFS(Base_Porao_Turno!$K:$K,Base_Porao_Turno!$A:$A,A14,Base_Porao_Turno!$E:$E,B14)) | E14: =IF(OR(C14="",D14=""),"",C14-D14) | F14: =IFERROR(D14/C14,"") | G14: =IF(A14="","",SUMIFS(Base_Porao_Turno!$H:$H,Base_Porao_Turno!$A:$A,A14,Base_Porao_Turno!$E:$E,B14)) | H14: =IFERROR(D14/G14,"")
D15: =IF(A15="","",SUMIFS(Base_Porao_Turno!$K:$K,Base_Porao_Turno!$A:$A,A15,Base_Porao_Turno!$E:$E,B15)) | E15: =IF(OR(C15="",D15=""),"",C15-D15) | F15: =IFERROR(D15/C15,"") | G15: =IF(A15="","",SUMIFS(Base_Porao_Turno!$H:$H,Base_Porao_Turno!$A:$A,A15,Base_Porao_Turno!$E:$E,B15)) | H15: =IFERROR(D15/G15,"")
D16: =IF(A16="","",SUMIFS(Base_Porao_Turno!$K:$K,Base_Porao_Turno!$A:$A,A16,Base_Porao_Turno!$E:$E,B16)) | E16: =IF(OR(C16="",D16=""),"",C16-D16) | F16: =IFERROR(D16/C16,"") | G16: =IF(A16="","",SUMIFS(Base_Porao_Turno!$H:$H,Base_Porao_Turno!$A:$A,A16,Base_Porao_Turno!$E:$E,B16)) | H16: =IFERROR(D16/G16,"")
D17: =IF(A17="","",SUMIFS(Base_Porao_Turno!$K:$K,Base_Porao_Turno!$A:$A,A17,Base_Porao_Turno!$E:$E,B17)) | E17: =IF(OR(C17="",D17=""),"",C17-D17) | F17: =IFERROR(D17/C17,"") | G17: =IF(A17="","",SUMIFS(Base_Porao_Turno!$H:$H,Base_Porao_Turno!$A:$A,A17,Base_Porao_Turno!$E:$E,B17)) | H17: =IFERROR(D17/G17,"")
D18: =IF(A18="","",SUMIFS(Base_Porao_Turno!$K:$K,Base_Porao_Turno!$A:$A,A18,Base_Porao_Turno!$E:$E,B18)) | E18: =IF(OR(C18="",D18=""),"",C18-D18) | F18: =IFERROR(D18/C18,"") | G18: =IF(A18="","",SUMIFS(Base_Porao_Turno!$H:$H,Base_Porao_Turno!$A:$A,A18,Base_Porao_Turno!$E:$E,B18)) | H18: =IFERROR(D18/G18,"")
D19: =IF(A19="","",SUMIFS(Base_Porao_Turno!$K:$K,Base_Porao_Turno!$A:$A,A19,Base_Porao_Turno!$E:$E,B19)) | E19: =IF(OR(C19="",D19=""),"",C19-D19) | F19: =IFERROR(D19/C19,"") | G19: =IF(A19="","",SUMIFS(Base_Porao_Turno!$H:$H,Base_Porao_Turno!$A:$A,A19,Base_Porao_Turno!$E:$E,B19)) | H19: =IFERROR(D19/G19,"")
D20: =IF(A20="","",SUMIFS(Base_Porao_Turno!$K:$K,Base_Porao_Turno!$A:$A,A20,Base_Porao_Turno!$E:$E,B20)) | E20: =IF(OR(C20="",D20=""),"",C20-D20) | F20: =IFERROR(D20/C20,"") | G20: =IF(A20="","",SUMIFS(Base_Porao_Turno!$H:$H,Base_Porao_Turno!$A:$A,A20,Base_Porao_Turno!$E:$E,B20)) | H20: =IFERROR(D20/G20,"")
D21: =IF(A21="","",SUMIFS(Base_Porao_Turno!$K:$K,Base_Porao_Turno!$A:$A,A21,Base_Porao_Turno!$E:$E,B21)) | E21: =IF(OR(C21="",D21=""),"",C21-D21) | F21: =IFERROR(D21/C21,"") | G21: =IF(A21="","",SUMIFS(Base_Porao_Turno!$H:$H,Base_Porao_Turno!$A:$A,A21,Base_Porao_Turno!$E:$E,B21)) | H21: =IFERROR(D21/G21,"")
D22: =IF(A22="","",SUMIFS(Base_Porao_Turno!$K:$K,Base_Porao_Turno!$A:$A,A22,Base_Porao_Turno!$E:$E,B22)) | E22: =IF(OR(C22="",D22=""),"",C22-D22) | F22: =IFERROR(D22/C22,"") | G22: =IF(A22="","",SUMIFS(Base_Porao_Turno!$H:$H,Base_Porao_Turno!$A:$A,A22,Base_Porao_Turno!$E:$E,B22)) | H22: =IFERROR(D22/G22,"")
D23: =IF(A23="","",SUMIFS(Base_Porao_Turno!$K:$K,Base_Porao_Turno!$A:$A,A23,Base_Porao_Turno!$E:$E,B23)) | E23: =IF(OR(C23="",D23=""),"",C23-D23) | F23: =IFERROR(D23/C23,"") | G23: =IF(A23="","",SUMIFS(Base_Porao_Turno!$H:$H,Base_Porao_Turno!$A:$A,A23,Base_Porao_Turno!$E:$E,B23)) | H23: =IFERROR(D23/G23,"")
D24: =IF(A24="","",SUMIFS(Base_Porao_Turno!$K:$K,Base_Porao_Turno!$A:$A,A24,Base_Porao_Turno!$E:$E,B24)) | E24: =IF(OR(C24="",D24=""),"",C24-D24) | F24: =IFERROR(D24/C24,"") | G24: =IF(A24="","",SUMIFS(Base_Porao_Turno!$H:$H,Base_Porao_Turno!$A:$A,A24,Base_Porao_Turno!$E:$E,B24)) | H24: =IFERROR(D24/G24,"")
... D601: =IF(A601="","",SUMIFS(Base_Porao_Turno!$K:$K,Base_Porao_Turno!$A:$A,A601,Base_Porao_Turno!$E:$E,B601)) | E601: =IF(OR(C601="",D601=""),"",C601-D601) | F601: =IFERROR(D601/C601,"") | G601: =IF(A601="","",SUMIFS(Base_Porao_Turno!$H:$H,Base_Porao_Turno!$A:$A,A601,Base_Porao_Turno!$E:$E,B601)) | H601: =IFERROR(D601/G601,"")

Sheet KPI_Resumo
A1: PAINEL DE KPIs – OPERAÇÃO SELECIONADA
A2: Operação Selecionada | B2: OP-003
A4: ETB | B4: =Cadastro_Navio!I4 -> 46237
A5: ETS | B5: =Cadastro_Navio!J4 -> 46242
A6: Volume Navio (t) | B6: =Cadastro_Navio!K4 -> 44031.65
A7: Volume Descarregado (t) | B7: =SUMIFS(Base_Porao_Turno!$K:$K,Base_Porao_Turno!$A:$A,$B$2) -> 6347.77
A8: Volume Terminal (t) | B8: =SUMIFS(Base_Porao_Turno!$I:$I,Base_Porao_Turno!$A:$A,$B$2) -> 6347.77
A9: Volume Direto (t) | B9: =SUMIFS(Base_Porao_Turno!$J:$J,Base_Porao_Turno!$A:$A,$B$2) -> 0
A10: Total Trabalhado (h) | B10: =SUMIFS(Base_Porao_Turno!$H:$H,Base_Porao_Turno!$A:$A,$B$2) -> 16.833333
A11: Total Paradas (h) | B11: =SUMIFS(Base_Porao_Turno!$G:$G,Base_Porao_Turno!$A:$A,$B$2) -> 1.1666667
A12: Total Operação (h) | B12: =SUMIFS(Base_Porao_Turno!$F:$F,Base_Porao_Turno!$A:$A,$B$2) -> 18
A13: % Parada Operacional | B13: =IFERROR(B11/B12,0) -> 0.064814815
A14: Eficiência Operacional | B14: =IFERROR(B10/B12,0) -> 0.93518519
A15: Produtividade Média (t/h) | B15: =IFERROR(B7/B10,0) -> 377.09525
A16: Média Descarga (t/dia) | B16: =IFERROR(B7/(B12/24),0) -> 8463.6933
A17: Tempo Médio porão (h) | B17: =IFERROR(AVERAGEIFS(Poroes_Resumo!$G:$G,Poroes_Resumo!$A:$A,$B$2,Poroes_Resumo!$D:$D,">0"),0) -> 16.833333
A18: Qtd Porões Operados | B18: =COUNTIFS(Poroes_Resumo!$A:$A,$B$2,Poroes_Resumo!$D:$D,">0") -> 1
A19: % Aderência ao Manifesto | B19: =IFERROR(B7/B6,0) -> 0.1441638

Sheet Metodologia_KPIs
A1: KPI | B1: Como obter | C1: Fonte primária | D1: Fórmula gerencial | E1: Leitura executiva
A2: Volume Descarregado (t) | B2: Somar o volume total lançado em cada turno e porão. | C2: Base_Porao_Turno[Volume Total (t)] | D2: Σ Volume Total | E2: Volume efetivamente movimentado do navio.
A3: Produtividade Média (t/h) | B3: Dividir o volume descarregado pelas horas efetivamente trabalhadas. | C3: Base_Porao_Turno[Volume Total, Horas Trabalhadas] | D3: Volume descarregado / Total trabalhado | E3: Mostra capacidade operacional real sem inflar resultado com horas paradas.
A4: Média Descarga (t/dia) | B4: Converter o total de horas calendário para dias e dividir o volume total. | C4: Base_Porao_Turno[Horas Calendário] | D4: Volume descarregado / (Horas calendário/24) | E4: Mostra ritmo de descarga percebido pela operação/cliente.
A5: Tempo Médio porão (h) | B5: Apurar horas trabalhadas por porão e tirar média apenas dos porões operados. | C5: Poroes_Resumo[Horas Trabalhadas] | D5: Média das horas por porão com descarga > 0 | E5: Indica balanceamento da operação entre porões.
A6: Total Paradas (h) | B6: Somar horas de paradas informadas por turno. | C6: Base_Porao_Turno[Horas Paradas] ou Paradas_Detalhadas[Horas Paradas] | D6: Σ Horas Paradas | E6: Evidencia perdas operacionais.
A7: % Parada Operacional | B7: Dividir horas de paradas pelas horas calendário. | C7: Base_Porao_Turno | D7: Total Paradas / Total Operação | E7: Permite atacar causas estruturais de perda.
A8: Eficiência Operacional | B8: Dividir horas trabalhadas pelas horas calendário. | C8: Base_Porao_Turno | D8: Total Trabalhado / Total Operação | E8: Mede aproveitamento do tempo disponível.
A9: % Aderência ao Manifesto | B9: Comparar o descarregado ao manifestado por navio. | C9: Cadastro_Navio + Base_Porao_Turno | D9: Volume descarregado / Volume manifestado | E9: Ajuda a detectar divergências de volume e reconciliação.
A10: Produtividade por porão | B10: Dividir volume descarregado do porão pelas horas trabalhadas do porão. | C10: Poroes_Resumo | D10: Volume do porão / Horas do porão | E10: Expõe gargalos localizados e desequilíbrio de sequenciamento.
A11: Paradas por categoria | B11: Classificar cada parada detalhada por categoria e consolidar horas. | C11: Paradas_Detalhadas | D11: Σ Horas por categoria | E11: Direciona ação corretiva: equipamento, clima, cliente, documentação etc.

Sheet Dashboard
A1: DASHBOARD EXECUTIVO – PRODUTIVIDADE DE DESCARGA
A3: Operação | B3: =KPI_Resumo!B2 -> OP-003 | D3: Navio | E3: =IFERROR(INDEX(Cadastro_Navio!$B$2:$B$198,MATCH($B$3,Cadastro_Navio!$A$2:$A$198,0)),"") -> IC Phoenix | G3: Terminal | H3: =IFERROR(INDEX(Cadastro_Navio!$E$2:$E$198,MATCH($B$3,Cadastro_Navio!$A$2:$A$198,0)),"") -> Imbituba
A5: Volume Descarregado (t) | D5: Produtividade Média (t/h) | G5: Média Descarga (t/dia) | J5: Eficiência Operacional
A6: =KPI_Resumo!B7 -> 6347.77 | D6: =KPI_Resumo!B15 -> 377.09525 | G6: =KPI_Resumo!B16 -> 8463.6933 | J6: =KPI_Resumo!B14 -> 0.93518519
A9: Total Paradas (h) | D9: % Parada Operacional | G9: Tempo Médio porão (h) | J9: % Aderência Manifesto
A10: =KPI_Resumo!B11 -> 1.1666667 | D10: =KPI_Resumo!B13 -> 0.064814815 | G10: =KPI_Resumo!B17 -> 16.833333 | J10: =KPI_Resumo!B19 -> 0.1441638
A14: Porão | B14: Manifestado | C14: Descarregado | D14: Saldo | E14: TPH | G14: Turno | H14: Volume | I14: Horas Trabalhadas | J14: TPH
A15: 1 | B15: =IFERROR(SUMIFS(Poroes_Resumo!$C:$C,Poroes_Resumo!$A:$A,$B$3,Poroes_Resumo!$B:$B,$A15),0) -> 10939.98 | C15: =IFERROR(SUMIFS(Poroes_Resumo!$D:$D,Poroes_Resumo!$A:$A,$B$3,Poroes_Resumo!$B:$B,$A15),0) -> 0 | D15: =B15-C15 -> 10939.98 | E15: =IFERROR(SUMIFS(Poroes_Resumo!$H:$H,Poroes_Resumo!$A:$A,$B$3,Poroes_Resumo!$B:$B,$A15),0) -> 0 | G15: A | H15: =IFERROR(SUMIFS(Base_Porao_Turno!$K:$K,Base_Porao_Turno!$A:$A,$B$3,Base_Porao_Turno!$C:$C,G15),0) -> 2013.59 | I15: =IFERROR(SUMIFS(Base_Porao_Turno!$H:$H,Base_Porao_Turno!$A:$A,$B$3,Base_Porao_Turno!$C:$C,G15),0) -> 5.1666667 | J15: =IFERROR(H15/I15,0) -> 389.7271
A16: 2 | B16: =IFERROR(SUMIFS(Poroes_Resumo!$C:$C,Poroes_Resumo!$A:$A,$B$3,Poroes_Resumo!$B:$B,$A16),0) -> 11393.14 | C16: =IFERROR(SUMIFS(Poroes_Resumo!$D:$D,Poroes_Resumo!$A:$A,$B$3,Poroes_Resumo!$B:$B,$A16),0) -> 6347.77 | D16: =B16-C16 -> 5045.37 | E16: =IFERROR(SUMIFS(Poroes_Resumo!$H:$H,Poroes_Resumo!$A:$A,$B$3,Poroes_Resumo!$B:$B,$A16),0) -> 377.09525 | G16: B | H16: =IFERROR(SUMIFS(Base_Porao_Turno!$K:$K,Base_Porao_Turno!$A:$A,$B$3,Base_Porao_Turno!$C:$C,G16),0) -> 0 | I16: =IFERROR(SUMIFS(Base_Porao_Turno!$H:$H,Base_Porao_Turno!$A:$A,$B$3,Base_Porao_Turno!$C:$C,G16),0) -> 0 | J16: =IFERROR(H16/I16,0) -> 0
A17: 3 | B17: =IFERROR(SUMIFS(Poroes_Resumo!$C:$C,Poroes_Resumo!$A:$A,$B$3,Poroes_Resumo!$B:$B,$A17),0) -> 0 | C17: =IFERROR(SUMIFS(Poroes_Resumo!$D:$D,Poroes_Resumo!$A:$A,$B$3,Poroes_Resumo!$B:$B,$A17),0) -> 0 | D17: =B17-C17 -> 0 | E17: =IFERROR(SUMIFS(Poroes_Resumo!$H:$H,Poroes_Resumo!$A:$A,$B$3,Poroes_Resumo!$B:$B,$A17),0) -> 0 | G17: C | H17: =IFERROR(SUMIFS(Base_Porao_Turno!$K:$K,Base_Porao_Turno!$A:$A,$B$3,Base_Porao_Turno!$C:$C,G17),0) -> 2219.11 | I17: =IFERROR(SUMIFS(Base_Porao_Turno!$H:$H,Base_Porao_Turno!$A:$A,$B$3,Base_Porao_Turno!$C:$C,G17),0) -> 5.8333333 | J17: =IFERROR(H17/I17,0) -> 380.41886
A18: 4 | B18: =IFERROR(SUMIFS(Poroes_Resumo!$C:$C,Poroes_Resumo!$A:$A,$B$3,Poroes_Resumo!$B:$B,$A18),0) -> 10802.34 | C18: =IFERROR(SUMIFS(Poroes_Resumo!$D:$D,Poroes_Resumo!$A:$A,$B$3,Poroes_Resumo!$B:$B,$A18),0) -> 0 | D18: =B18-C18 -> 10802.34 | E18: =IFERROR(SUMIFS(Poroes_Resumo!$H:$H,Poroes_Resumo!$A:$A,$B$3,Poroes_Resumo!$B:$B,$A18),0) -> 0 | G18: D | H18: =IFERROR(SUMIFS(Base_Porao_Turno!$K:$K,Base_Porao_Turno!$A:$A,$B$3,Base_Porao_Turno!$C:$C,G18),0) -> 2115.07 | I18: =IFERROR(SUMIFS(Base_Porao_Turno!$H:$H,Base_Porao_Turno!$A:$A,$B$3,Base_Porao_Turno!$C:$C,G18),0) -> 5.8333333 | J18: =IFERROR(H18/I18,0) -> 362.58343
A19: 5 | B19: =IFERROR(SUMIFS(Poroes_Resumo!$C:$C,Poroes_Resumo!$A:$A,$B$3,Poroes_Resumo!$B:$B,$A19),0) -> 10896.19 | C19: =IFERROR(SUMIFS(Poroes_Resumo!$D:$D,Poroes_Resumo!$A:$A,$B$3,Poroes_Resumo!$B:$B,$A19),0) -> 0 | D19: =B19-C19 -> 10896.19 | E19: =IFERROR(SUMIFS(Poroes_Resumo!$H:$H,Poroes_Resumo!$A:$A,$B$3,Poroes_Resumo!$B:$B,$A19),0) -> 0
A20: 6 | B20: =IFERROR(SUMIFS(Poroes_Resumo!$C:$C,Poroes_Resumo!$A:$A,$B$3,Poroes_Resumo!$B:$B,$A20),0) -> 0 | C20: =IFERROR(SUMIFS(Poroes_Resumo!$D:$D,Poroes_Resumo!$A:$A,$B$3,Poroes_Resumo!$B:$B,$A20),0) -> 0 | D20: =B20-C20 -> 0 | E20: =IFERROR(SUMIFS(Poroes_Resumo!$H:$H,Poroes_Resumo!$A:$A,$B$3,Poroes_Resumo!$B:$B,$A20),0) -> 0
A21: 7 | B21: =IFERROR(SUMIFS(Poroes_Resumo!$C:$C,Poroes_Resumo!$A:$A,$B$3,Poroes_Resumo!$B:$B,$A21),0) -> 0 | C21: =IFERROR(SUMIFS(Poroes_Resumo!$D:$D,Poroes_Resumo!$A:$A,$B$3,Poroes_Resumo!$B:$B,$A21),0) -> 0 | D21: =B21-C21 -> 0 | E21: =IFERROR(SUMIFS(Poroes_Resumo!$H:$H,Poroes_Resumo!$A:$A,$B$3,Poroes_Resumo!$B:$B,$A21),0) -> 0 | G21: Categoria | H21: Horas
A22: 8 | B22: =IFERROR(SUMIFS(Poroes_Resumo!$C:$C,Poroes_Resumo!$A:$A,$B$3,Poroes_Resumo!$B:$B,$A22),0) -> 0 | C22: =IFERROR(SUMIFS(Poroes_Resumo!$D:$D,Poroes_Resumo!$A:$A,$B$3,Poroes_Resumo!$B:$B,$A22),0) -> 0 | D22: =B22-C22 -> 0 | E22: =IFERROR(SUMIFS(Poroes_Resumo!$H:$H,Poroes_Resumo!$A:$A,$B$3,Poroes_Resumo!$B:$B,$A22),0) -> 0 | G22: Clima | H22: =IFERROR(SUMIFS(Paradas_Detalhadas!$I:$I,Paradas_Detalhadas!$A:$A,$B$3,Paradas_Detalhadas!$E:$E,G22),0) -> 0.16666667
A23: 9 | B23: =IFERROR(SUMIFS(Poroes_Resumo!$C:$C,Poroes_Resumo!$A:$A,$B$3,Poroes_Resumo!$B:$B,$A23),0) -> 0 | C23: =IFERROR(SUMIFS(Poroes_Resumo!$D:$D,Poroes_Resumo!$A:$A,$B$3,Poroes_Resumo!$B:$B,$A23),0) -> 0 | D23: =B23-C23 -> 0 | E23: =IFERROR(SUMIFS(Poroes_Resumo!$H:$H,Poroes_Resumo!$A:$A,$B$3,Poroes_Resumo!$B:$B,$A23),0) -> 0 | G23: Equipamento | H23: =IFERROR(SUMIFS(Paradas_Detalhadas!$I:$I,Paradas_Detalhadas!$A:$A,$B$3,Paradas_Detalhadas!$E:$E,G23),0) -> 0
A24: 10 | B24: =IFERROR(SUMIFS(Poroes_Resumo!$C:$C,Poroes_Resumo!$A:$A,$B$3,Poroes_Resumo!$B:$B,$A24),0) -> 0 | C24: =IFERROR(SUMIFS(Poroes_Resumo!$D:$D,Poroes_Resumo!$A:$A,$B$3,Poroes_Resumo!$B:$B,$A24),0) -> 0 | D24: =B24-C24 -> 0 | E24: =IFERROR(SUMIFS(Poroes_Resumo!$H:$H,Poroes_Resumo!$A:$A,$B$3,Poroes_Resumo!$B:$B,$A24),0) -> 0 | G24: Operacional | H24: =IFERROR(SUMIFS(Paradas_Detalhadas!$I:$I,Paradas_Detalhadas!$A:$A,$B$3,Paradas_Detalhadas!$E:$E,G24),0) -> 0.5
A25: 11 | B25: =IFERROR(SUMIFS(Poroes_Resumo!$C:$C,Poroes_Resumo!$A:$A,$B$3,Poroes_Resumo!$B:$B,$A25),0) -> 0 | C25: =IFERROR(SUMIFS(Poroes_Resumo!$D:$D,Poroes_Resumo!$A:$A,$B$3,Poroes_Resumo!$B:$B,$A25),0) -> 0 | D25: =B25-C25 -> 0 | E25: =IFERROR(SUMIFS(Poroes_Resumo!$H:$H,Poroes_Resumo!$A:$A,$B$3,Poroes_Resumo!$B:$B,$A25),0) -> 0 | G25: Manutenção | H25: =IFERROR(SUMIFS(Paradas_Detalhadas!$I:$I,Paradas_Detalhadas!$A:$A,$B$3,Paradas_Detalhadas!$E:$E,G25),0) -> 0
A26: 12 | B26: =IFERROR(SUMIFS(Poroes_Resumo!$C:$C,Poroes_Resumo!$A:$A,$B$3,Poroes_Resumo!$B:$B,$A26),0) -> 0 | C26: =IFERROR(SUMIFS(Poroes_Resumo!$D:$D,Poroes_Resumo!$A:$A,$B$3,Poroes_Resumo!$B:$B,$A26),0) -> 0 | D26: =B26-C26 -> 0 | E26: =IFERROR(SUMIFS(Poroes_Resumo!$H:$H,Poroes_Resumo!$A:$A,$B$3,Poroes_Resumo!$B:$B,$A26),0) -> 0 | G26: Aguardando Cliente | H26: =IFERROR(SUMIFS(Paradas_Detalhadas!$I:$I,Paradas_Detalhadas!$A:$A,$B$3,Paradas_Detalhadas!$E:$E,G26),0) -> 0
G27: Aguardando Documentação | H27: =IFERROR(SUMIFS(Paradas_Detalhadas!$I:$I,Paradas_Detalhadas!$A:$A,$B$3,Paradas_Detalhadas!$E:$E,G27),0) -> 0
G28: Segurança | H28: =IFERROR(SUMIFS(Paradas_Detalhadas!$I:$I,Paradas_Detalhadas!$A:$A,$B$3,Paradas_Detalhadas!$E:$E,G28),0) -> 0.5
G29: Sem Energia | H29: =IFERROR(SUMIFS(Paradas_Detalhadas!$I:$I,Paradas_Detalhadas!$A:$A,$B$3,Paradas_Detalhadas!$E:$E,G29),0) -> 0
G30: Outros | H30: =IFERROR(SUMIFS(Paradas_Detalhadas!$I:$I,Paradas_Detalhadas!$A:$A,$B$3,Paradas_Detalhadas!$E:$E,G30),0) -> 0

Sheet Auditoria_Correcoes
A1: Item | B1: Aba/Celula | C1: Antes/Problema | D1: Depois/Correcao
A2: Operacao ID | B2: Cadastro_Navio!A2 | C2: Valor numerico 1, divergente de OP-001 | D2: OP-001
A3: Operacao ID | B3: Paradas_Detalhadas!A2:A3 | C3: Valor numerico 1, nao somava no Dashboard | D3: OP-001
A4: ETS | B4: Cadastro_Navio!J2 | C4: 31/06/2026, data inexistente | D4: 30/06/2026
A5: % Parada Operacional | B5: KPI_Resumo!B13 | C5: B10/B11/100 | D5: B11/B12
A6: Eficiencia Operacional | B6: KPI_Resumo!B14 | C6: B7/B11/1000 | D6: B10/B12
A7: Produtividade Media | B7: KPI_Resumo!B15 | C7: B6/B9 | D7: B7/B10
A8: Media Descarga diaria | B8: KPI_Resumo!B16 | C8: B6/(B11/24) | D8: B7/(B12/24)
A9: Aderencia ao Manifesto | B9: KPI_Resumo!B19 | C9: B6/B5 | D9: B7/B6
A10: Nome do navio no Dashboard | B10: Dashboard!E3 | C10: _xludf.XLOOKUP podia nao retornar em algumas versoes/configuracoes | D10: INDEX/MATCH buscando Cadastro_Navio!B por Operacao ID
A11: Terminal no Dashboard | B11: Dashboard!H3 | C11: _xludf.XLOOKUP podia nao retornar em algumas versoes/configuracoes | D11: INDEX/MATCH buscando Cadastro_Navio!E por Operacao ID
A12: Horas Trabalhadas | B12: Base_Porao_Turno!G:H | C12: Horas paradas digitadas como 1,55 eram tratadas como 1,55 hora decimal | D12: Horas paradas calculadas por SUMIFS de Paradas_Detalhadas; 1h55 = 1,9167h e 6h - 1h55 = 4h05
A13: OP-002 | B13: Correção de linhas com volume direto sem Operacao ID e sem cálculo de horas | C13: Linhas corrigidas: 40, 41, 42, 43, 44, 45 | D13: Horas paradas preenchidas a partir da aba Paradas_Detalhadas por Data + Turno
